<?xml version="1.0"?>

<sdf version='1.6'>
	<model name="robotic_arm">
		<% 
			gravity = 0
			
			tube_length = 0.2
			tube_radius = 0.01
			tube_mass 	= 0.1
			servo_mass	= 0.3
			gripper_mass= 0.25
			
			def box_inertia(mass, x, y, z)
				ixx = 1.0/12.0*mass*(z*z + y*y)
				iyy = 1.0/12.0*mass*(z*z + x*x)
				izz = 1.0/12.0*mass*(x*x + y*y)
				return ixx, iyy, izz
			end
			
			def cylinder_inertia(mass, l, r)
				ixx = mass*(3.0*r*r + l*l) / 12.0
				izz = mass*r*r/2.0
				iyy = mass*(3.0*r*r + l*l) / 12.0
				return ixx, iyy, izz
			end
		%>
		<static>false</static>
		<!-- Ombro -->
		<link name="ombro_link">
			<gravity> <%= gravity %> </gravity>
			<pose> 0 0 1 0 0 0 </pose>
			<frame name="ombro_frame"/>
			<% 	x = 0.1
				y = 0.05
				z = 0.05 %>
			<visual name="ombro_visual">
				<geometry>
					<box>
						<size> <%=x%> <%=y%> <%=z%> </size>
					</box>
				</geometry>
				<material>
					<ambient>0 0.4 0 1</ambient>
					<diffuse>0 0.4 0 1</diffuse>
					<specular>0 0 0 1</specular>
					<emissive>0 0 0 0</emissive>
				</material>
			</visual>
			<collision name="ombro_collision">
				<geometry>
					<box>
						<size> <%=x%> <%=y%> <%=z%> </size>
					</box>
				</geometry>
			</collision>
			<inertial>
				<mass> <%= servo_mass %> </mass>
				<inertia>
					<% ixx, iyy, izz = box_inertia(servo_mass, x, y, z) %>
					<ixx> <%=ixx%> </ixx>
					<iyy> <%=iyy%> </iyy>
					<izz> <%=izz%> </izz>
					<ixy>0.0</ixy>
					<ixz>0.0</ixz>
					<iyz>0.0</iyz>
				</inertia>
			</inertial>
		</link>
		
		<!-- Box0 -->
		<link name="Box0_link">
			<gravity> <%= gravity %> </gravity>
			<% 	x = 0.06
				y = 0.04
				z = 0.03
				box0_y = y*2.5%>
			<pose> 0 <%=y*2.0%> 1 0 0 0 </pose>
			<visual name="Box0_visual">
				<geometry>
					<box>
						<size> <%=x%> <%=y%> <%=z%> </size>
					</box>
				</geometry>
				<material>
					<ambient>0 0 0 1</ambient>
					<diffuse>0 0 0 1</diffuse>
					<specular>0 0 0 1</specular>
					<emissive>0 0 0 0</emissive>
				</material>
			</visual>
			<collision name="Box0_collision">
				<geometry>
					<box>
						<size> <%=x%> <%=y%> <%=z%> </size>
					</box>
				</geometry>
			</collision>
			<inertial>
				<mass> <%= servo_mass %> </mass>
				<inertia>
					<% ixx, iyy, izz = box_inertia(servo_mass, x, y, z) %>
					<ixx> <%=ixx%> </ixx>
					<iyy> <%=iyy%> </iyy>
					<izz> <%=izz%> </izz>
					<ixy> 0.0 </ixy>
					<ixz> 0.0 </ixz>
					<iyz> 0.0 </iyz>
				</inertia>
			</inertial>
		</link>
		
		<!-- UMERO -->
		<link name="Tube0_link">
			<gravity> <%= gravity %> </gravity>
			<% umero_y = box0_y + tube_length%>
			<pose> 0 <%= box0_y %> 1 0 0 0 </pose>
			<visual name="Tube0_visual">
				<pose> 0 <%=tube_length/2%> 0 1.57075 0 0 </pose>
				<geometry>
					<cylinder>
						<length> <%= tube_length %> </length>
						<radius> <%= tube_radius %> </radius>
					</cylinder>
				</geometry>
				<material>
					<ambient>0.6 0.6 0.6 1</ambient>
					<diffuse>0.6 0.6 0.6 1</diffuse>
					<specular>0 0 0 1</specular>
					<emissive>0 0 0 0</emissive>
				</material>
			</visual>
			<collision name="Tube0_collision">
				<pose> 0 <%=tube_length/2%> 0 1.57075 0 0 </pose>
				<geometry>
					<cylinder>
						<length> <%= tube_length %> </length>
						<radius> <%= tube_radius %> </radius>
					</cylinder>
				</geometry>
			</collision>
			<inertial>
				<pose> 0 <%=tube_length/2%> 0 1.57075 0 0 </pose>
				<mass> <%= tube_mass %> </mass>
				<inertia>
					<% ixx, iyy, izz = cylinder_inertia(tube_mass, tube_length, tube_radius) %>
					<ixx> <%=ixx%> </ixx>
					<iyy> <%=iyy%> </iyy>
					<izz> <%=izz%> </izz>
					<ixy> 0.0 </ixy>
					<ixz> 0.0 </ixz>
					<iyz> 0.0 </iyz>
				</inertia>
			</inertial>
		</link>
		
		<!-- Box1 -->
		<link name="Box1_link">
			<gravity> <%= gravity %> </gravity>
			<% 	x = 0.03
				y = 0.05
				z = 0.02 
				Box1_y = umero_y+y%>
			<pose> 0 <%=umero_y+y/2.0%> 1 0 0 0 </pose>
			<visual name="Box1_visual">
				<geometry>
					<box>
						<size> <%=x%> <%=y%> <%=z%> </size>
					</box>
				</geometry>
				<material>
					<ambient>0 0 0 1</ambient>
					<diffuse>0 0 0 1</diffuse>
					<specular>0 0 0 1</specular>
					<emissive>0 0 0 0</emissive>
				</material>
			</visual>
			<collision name="Box1_collision">
				<geometry>
					<box>
						<size> <%=x%> <%=y%> <%=z%> </size>
					</box>
				</geometry>
			</collision>
			<inertial>
				<mass> <%= servo_mass %> </mass>
				<inertia>
					<% ixx, iyy, izz = box_inertia(servo_mass, x, y, z) %>
					<ixx> <%=ixx%> </ixx>
					<iyy> <%=iyy%> </iyy>
					<izz> <%=izz%> </izz>
					<ixy> 0.0 </ixy>
					<ixz> 0.0 </ixz>
					<iyz> 0.0 </iyz>
				</inertia>
			</inertial>
		</link>
		
		<!-- Box2 -->
		<link name="Box2_link">
			<gravity> <%= gravity %> </gravity>
			<% 	x = 0.05
				y = 0.03
				z = 0.02 
				Box2_y = Box1_y + 0.02 + y %>
			<pose> 0 <%= Box1_y + 0.02 + y/2.0 %> 1 0 0 0 </pose>
			<visual name="Box2_visual">
				<geometry>
					<box>
						<size> <%=x%> <%=y%> <%=z%> </size>
					</box>
				</geometry>
				<material>
					<ambient>0 0 0 1</ambient>
					<diffuse>0 0 0 1</diffuse>
					<specular>0 0 0 1</specular>
					<emissive>0 0 0 0</emissive>
				</material>
			</visual>
			<collision name="Box2_collision">
				<geometry>
					<box>
						<size> <%=x%> <%=y%> <%=z%> </size>
					</box>
				</geometry>
			</collision>
			<inertial>
				<mass> <%= servo_mass %> </mass>
				<inertia>
					<% ixx, iyy, izz = box_inertia(servo_mass, x, y, z) %>
					<ixx> <%=ixx%> </ixx>
					<iyy> <%=iyy%> </iyy>
					<izz> <%=izz%> </izz>
					<ixy> 0.0 </ixy>
					<ixz> 0.0 </ixz>
					<iyz> 0.0 </iyz>
				</inertia>
			</inertial>
		</link>
		
		<!-- Tube1 -->
		<link name="Tube1_link">
			<gravity> <%= gravity %> </gravity>
			<% Tube1_y = Box2_y + tube_length%>
			<pose> 0 <%= Box2_y %> 1 0 0 0 </pose>
			<visual name="Tube1_visual">
				<pose> 0 <%=tube_length/2%> 0 1.57075 0 0 </pose>
				<geometry>
					<cylinder>
						<length> <%= tube_length %> </length>
						<radius> <%= tube_radius %> </radius>
					</cylinder>
				</geometry>
				<material>
					<ambient>0.6 0.6 0.6 1</ambient>
					<diffuse>0.6 0.6 0.6 1</diffuse>
					<specular>0 0 0 1</specular>
					<emissive>0 0 0 0</emissive>
				</material>
			</visual>
			<collision name="Tube1_collision">
				<pose> 0 <%=tube_length/2%> 0 1.57075 0 0 </pose>
				<geometry>
					<cylinder>
						<length> <%= tube_length %> </length>
						<radius> <%= tube_radius %> </radius>
					</cylinder>
				</geometry>
			</collision>
			<inertial>
				<pose> 0 <%=tube_length/2%> 0 1.57075 0 0 </pose>
				<mass> <%= tube_mass %> </mass>
				<inertia>
					<% ixx, iyy, izz = cylinder_inertia(tube_mass, tube_length, tube_radius) %>
					<ixx> <%=ixx%> </ixx>
					<iyy> <%=iyy%> </iyy>
					<izz> <%=izz%> </izz>
					<ixy> 0.0 </ixy>
					<ixz> 0.0 </ixz>
					<iyz> 0.0 </iyz>
				</inertia>
			</inertial>
		</link>
		
		<!-- Box3 -->
		<link name="Box3_link">
			<gravity> <%= gravity %> </gravity>
			<% 	x = 0.03
				y = 0.05
				z = 0.02 
				Box3_y = Box2_y + tube_length + y %>
			<pose> 0 <%= Box2_y + tube_length + y/2.0 %> 1 0 0 0 </pose>
			<visual name="Box3_visual">
				<geometry>
					<box>
						<size> <%=x%> <%=y%> <%=z%> </size>
					</box>
				</geometry>
				<material>
					<ambient>0 0 0 1</ambient>
					<diffuse>0 0 0 1</diffuse>
					<specular>0 0 0 1</specular>
					<emissive>0 0 0 0</emissive>
				</material>
			</visual>
			<collision name="Box3_collision">
				<geometry>
					<box>
						<size> <%=x%> <%=y%> <%=z%> </size>
					</box>
				</geometry>
			</collision>
			<inertial>
				<mass> <%= servo_mass %> </mass>
				<inertia>
					<% ixx, iyy, izz = box_inertia(servo_mass, x, y, z) %>
					<ixx> <%=ixx%> </ixx>
					<iyy> <%=iyy%> </iyy>
					<izz> <%=izz%> </izz>
					<ixy> 0.0 </ixy>
					<ixz> 0.0 </ixz>
					<iyz> 0.0 </iyz>
				</inertia>
			</inertial>
		</link>
		
		<!-- Gripper -->
		<link name="Gripper_link">
			<gravity> <%= gravity %> </gravity>
			<% 	x = 0.1
				y = 0.1
				z = 0.03 %>
			<pose> 0 <%= Box3_y + 0.02 + y/2.0 %> 1 0 0 0 </pose>
			<visual name="Gripper_visual">
				<geometry>
					<box>
						<size> <%=x%> <%=y%> <%=z%> </size>
					</box>
				</geometry>
				<material>
					<ambient>0 0 0.5 1</ambient>
					<diffuse>0 0 0.5 1</diffuse>
					<specular>0 0 0 1</specular>
					<emissive>0 0 0 0</emissive>
				</material>
			</visual>
			<collision name="Gripper_collision">
				<geometry>
					<box>
						<size> <%=x%> <%=y%> <%=z%> </size>
					</box>
				</geometry>
			</collision>
			<inertial>
				<mass> <%= gripper_mass %> </mass>
				<inertia>
					<% ixx, iyy, izz = box_inertia(gripper_mass, x, y, z) %>
					<ixx> <%=ixx%> </ixx>
					<iyy> <%=iyy%> </iyy>
					<izz> <%=izz%> </izz>
					<ixy> 0.0 </ixy>
					<ixz> 0.0 </ixz>
					<iyz> 0.0 </iyz>
				</inertia>
			</inertial>
		</link>

		<!-- Joints -->
		<joint name="joint0" type="fixed">
			<gravity> <% gravity %> </gravity>
			<parent>world</parent>
			<child>ombro_link</child>
			<pose> 0 0 1 0 0 0 </pose>
		</joint>
		
		<joint name="joint1" type="revolute">
			<parent>ombro_link</parent>
			<child>Box0_link</child>
			<pose> 0 -0.08 0 0 0 0 </pose>
			<axis>
				<xyz>1 0 0</xyz>
				<limit>
					<lower>-1.57075</lower>
					<upper>1.57075</upper>
					<effort>10000</effort>
					<velocity>0.01</velocity>
				</limit>
			</axis>
		</joint>
		
		<joint name="joint2" type="revolute">
			<gravity> <% gravity %> </gravity>
			<parent>Box0_link</parent>
			<child>Tube0_link</child>
			<pose> 0 0 0 0 0 0 </pose>
			<axis>
				<xyz>0 1 0</xyz>
				<limit>
					<lower>-3.1416</lower>
					<upper>3.1416</upper>
					<effort>100</effort>
					<velocity>0.01</velocity>
				</limit>
			</axis>
		</joint>
		
		<joint name="joint3" type="fixed">
			<parent>Tube0_link</parent>
			<child>Box1_link</child>
			<pose> 0 0 0 0 0 0 </pose>
		</joint>
		
		<joint name="joint4" type="revolute">
			<parent>Box1_link</parent>
			<child>Box2_link</child>
			<pose> 0 <%= -0.02-0.015 %> 0 0 0 0 </pose>
			<axis>
				<xyz>1 0 0</xyz>
				<limit>
					<lower>-3</lower>
					<upper>3</upper>
					<effort>100</effort>
					<velocity>0.01</velocity>
				</limit>
			</axis>
		</joint>
		
		<joint name="joint5" type="revolute">
			<parent>Box2_link</parent>
			<child>Tube1_link</child>
			<pose> 0 0 0 0 0 0 </pose>
			<axis>
				<xyz>0 1 0</xyz>
				<limit>
					<lower>-3.1416</lower>
					<upper>3.1416</upper>
					<effort>100</effort>
					<velocity>0.01</velocity>
				</limit>
			</axis>
		</joint>
		
		<joint name="joint6" type="fixed">
			<parent>Tube1_link</parent>
			<child>Box3_link</child>
			<pose> 0 0 0 0 0 0 </pose>
		</joint>
		
		<joint name="joint7" type="revolute">
			<parent>Box3_link</parent>
			<child>Gripper_link</child>
			<pose> 0 -0.08 0 0 0 0 </pose>
			<axis>
				<xyz>1 0 0</xyz>
				<limit>
					<lower>-2</lower>
					<upper>2</upper>
					<effort>100</effort>
					<velocity>0.01</velocity>
				</limit>
			</axis>
		</joint>
		
	</model>
</sdf>
