<?xml version="1.0" encoding="utf-8"?>
<!-- =================================================================================== -->
<!-- |    This document was autogenerated by xacro from model.urdf.xacro               | -->
<!-- |    EDITING THIS FILE BY HAND IS NOT RECOMMENDED                                 | -->
<!-- =================================================================================== -->
<robot name="simple_movel_arm" xmlns:xacro="http://www.ros.org/wiki/xacro">
  <link name="Box0_link">
    <visual>
      <geometry>
        <box size="0.06 0.04 0.03"/>
      </geometry>
      <origin rpy="0 0 0" xyz="-0.01 0.055 0"/>
    </visual>
    <collision>
      <origin rpy="0 0 0" xyz="-0.01 0.055 0"/>
      <geometry>
        <box size="0.06 0.04 0.03"/>
      </geometry>
    </collision>
    <inertial>
      <origin rpy="0 0 0" xyz="-0.01 0.055 0"/>
      <mass value="0.3"/>
      <inertia ixx="6.25e-05" ixy="0.0" ixz="0.0" iyy="0.0001125" iyz="0.0" izz="0.00013"/>
    </inertial>
  </link>
  <link name="Box1_link">
    <visual>
      <geometry>
        <box size="0.03 0.05 0.02"/>
      </geometry>
      <origin rpy="0 0 0" xyz="0 0.025 0"/>
    </visual>
    <collision>
      <origin rpy="0 0 0" xyz="0 0.025 0"/>
      <geometry>
        <box size="0.03 0.05 0.02"/>
      </geometry>
    </collision>
    <inertial>
      <origin rpy="0 0 0" xyz="0 0.025 0"/>
      <mass value="0.3"/>
      <inertia ixx="7.25e-05" ixy="0.0" ixz="0.0" iyy="3.25e-05" iyz="0.0" izz="8.5e-05"/>
    </inertial>
  </link>
  <link name="Box2_link">
    <visual>
      <geometry>
        <box size="0.05 0.03 0.02"/>
      </geometry>
      <origin rpy="0 0 0" xyz="-0.015 0.04 0"/>
    </visual>
    <collision>
      <origin rpy="0 0 0" xyz="-0.015 0.04 0"/>
      <geometry>
        <box size="0.05 0.03 0.02"/>
      </geometry>
    </collision>
    <inertial>
      <origin rpy="0 0 0" xyz="-0.015 0.04 0"/>
      <mass value="0.3"/>
      <inertia ixx="3.25e-05" ixy="0.0" ixz="0.0" iyy="7.25e-05" iyz="0.0" izz="8.5e-05"/>
    </inertial>
  </link>
  <link name="Box3_link">
    <visual>
      <geometry>
        <box size="0.03 0.05 0.02"/>
      </geometry>
      <origin rpy="0 0 0" xyz="0 0.026 0"/>
    </visual>
    <collision>
      <origin rpy="0 0 0" xyz="0 0.026 0"/>
      <geometry>
        <box size="0.03 0.05 0.02"/>
      </geometry>
    </collision>
    <inertial>
      <origin rpy="0 0 0" xyz="0 0.026 0"/>
      <mass value="0.3"/>
      <inertia ixx="7.25e-05" ixy="0.0" ixz="0.0" iyy="3.25e-05" iyz="0.0" izz="8.5e-05"/>
    </inertial>
  </link>
  <link name="Tube0_link">
    <visual>
      <geometry>
        <cylinder length="0.2" radius="0.01"/>
      </geometry>
      <origin rpy="1.57075 0 0" xyz="0 0.1 0"/>
    </visual>
    <collision>
      <origin rpy="1.57075 0 0" xyz="0 0.1 0"/>
      <geometry>
        <cylinder length="0.2" radius="0.01"/>
      </geometry>
    </collision>
    <inertial>
      <origin rpy="1.57075 0 0" xyz="0 0.1 0"/>
      <mass value="0.1"/>
      <inertia ixx="0.000335833333333" ixy="0" ixz="0" iyy="5e-06" iyz="0" izz="0.000335833333333"/>
    </inertial>
  </link>
  <link name="Tube1_link">
    <visual>
      <geometry>
        <cylinder length="0.2" radius="0.01"/>
      </geometry>
      <origin rpy="1.57075 0 0" xyz="0 0.1 0"/>
    </visual>
    <collision>
      <origin rpy="1.57075 0 0" xyz="0 0.1 0"/>
      <geometry>
        <cylinder length="0.2" radius="0.01"/>
      </geometry>
    </collision>
    <inertial>
      <origin rpy="1.57075 0 0" xyz="0 0.1 0"/>
      <mass value="0.1"/>
      <inertia ixx="0.000335833333333" ixy="0" ixz="0" iyy="5e-06" iyz="0" izz="0.000335833333333"/>
    </inertial>
  </link>
  <link name="ombro_link">
    <visual>
      <geometry>
        <cylinder length="0.1" radius="0.025"/>
      </geometry>
      <origin rpy="0 1.57075 0"/>
    </visual>
    <collision>
      <origin rpy="0 1.57075 0"/>
      <geometry>
        <cylinder length="0.1" radius="0.025"/>
      </geometry>
    </collision>
    <inertial>
      <origin rpy="0 1.57075 0"/>
      <mass value="0.5"/>
      <inertia ixx="0.000494791666667" ixy="0" ixz="0" iyy="0.00015625" iyz="0" izz="0.000494791666667"/>
    </inertial>
  </link>
  <link name="gripper_link">
    <visual>
      <geometry>
        <box size="0.1 0.1 0.03"/>
      </geometry>
      <origin xyz="0 0.07 0"/>
    </visual>
    <collision>
      <origin xyz="0 0.07 0"/>
      <geometry>
        <box size="0.1 0.1 0.03"/>
      </geometry>
    </collision>
    <inertial>
      <origin xyz="0 0.07 0"/>
      <mass value="0.3"/>
      <inertia ixx="0.0002725" ixy="0.0" ixz="0.0" iyy="0.0002725" iyz="0.0" izz="0.0005"/>
    </inertial>
  </link>
  <!-- Revolute Joints -->
  <joint name="joint1" type="revolute">
    <parent link="ombro_link"/>
    <child link="Box0_link"/>
    <origin xyz="0 0 0"/>
    <limit effort="1000" lower="-1.57075" upper="1.57075" velocity="10"/>
    <axis xyz="1 0 0"/>
  </joint>
  <joint name="joint2" type="revolute">
    <parent link="Box0_link"/>
    <child link="Tube0_link"/>
    <origin xyz="0 0.075 0"/>
    <limit effort="1000" lower="-1.57075" upper="1.57075" velocity="10"/>
    <axis xyz="0 1 0"/>
  </joint>
  <joint name="joint4" type="revolute">
    <parent link="Box1_link"/>
    <child link="Box2_link"/>
    <origin xyz="0 0.04 0"/>
    <limit effort="1000" lower="-3.14" upper="3.14" velocity="10"/>
    <axis xyz="1 0 0"/>
  </joint>
  <joint name="joint5" type="revolute">
    <parent link="Box2_link"/>
    <child link="Tube1_link"/>
    <origin xyz="0 0.055 0"/>
    <limit effort="1000" lower="-3.14" upper="3.14" velocity="10"/>
    <axis xyz="0 1 0"/>
  </joint>
  <joint name="joint7" type="revolute">
    <parent link="Box3_link"/>
    <child link="gripper_link"/>
    <origin xyz="0 0.04 0"/>
    <limit effort="1000" lower="-1.57075" upper="1.57075" velocity="10"/>
    <axis xyz="1 0 0"/>
  </joint>
  <!-- Fixed joints -->
  <joint name="joint3" type="fixed">
    <parent link="Tube1_link"/>
    <child link="Box3_link"/>
    <origin xyz="0 0.2 0"/>
  </joint>
  <joint name="joint6" type="fixed">
    <parent link="Tube0_link"/>
    <child link="Box1_link"/>
    <origin xyz="0 0.2 0"/>
  </joint>
  <transmission name="joint1_trans">
    <type>transmission_interface/SimpleTransmission</type>
    <joint name="joint1">
      <hardwareInterface>hardware_interface/VelocityJointInterface</hardwareInterface>
    </joint>
    <actuator name="joint1_motor">
      <mechanicalReduction>1</mechanicalReduction>
      <hardwareInterface>hardware_interface/VelocityJointInterface</hardwareInterface>
    </actuator>
  </transmission>
  <transmission name="joint2_trans">
    <type>transmission_interface/SimpleTransmission</type>
    <joint name="joint2">
      <hardwareInterface>hardware_interface/VelocityJointInterface</hardwareInterface>
    </joint>
    <actuator name="joint2_motor">
      <mechanicalReduction>1</mechanicalReduction>
      <hardwareInterface>hardware_interface/VelocityJointInterface</hardwareInterface>
    </actuator>
  </transmission>
  <transmission name="joint4_trans">
    <type>transmission_interface/SimpleTransmission</type>
    <joint name="joint4">
      <hardwareInterface>hardware_interface/VelocityJointInterface</hardwareInterface>
    </joint>
    <actuator name="joint4_motor">
      <mechanicalReduction>1</mechanicalReduction>
      <hardwareInterface>hardware_interface/VelocityJointInterface</hardwareInterface>
    </actuator>
  </transmission>
  <transmission name="joint5_trans">
    <type>transmission_interface/SimpleTransmission</type>
    <joint name="joint5">
      <hardwareInterface>hardware_interface/VelocityJointInterface</hardwareInterface>
    </joint>
    <actuator name="joint5_motor">
      <mechanicalReduction>1</mechanicalReduction>
      <hardwareInterface>hardware_interface/VelocityJointInterface</hardwareInterface>
    </actuator>
  </transmission>
  <transmission name="joint7_trans">
    <type>transmission_interface/SimpleTransmission</type>
    <joint name="joint7">
      <hardwareInterface>hardware_interface/VelocityJointInterface</hardwareInterface>
    </joint>
    <actuator name="joint7_motor">
      <mechanicalReduction>1</mechanicalReduction>
      <hardwareInterface>hardware_interface/VelocityJointInterface</hardwareInterface>
    </actuator>
  </transmission>
  <!-- Gazebo plugin -->
  <gazebo>
    <plugin filename="libgazebo_ros_control.so" name="gazebo_ros_control">
      <robotNamespace>/robotic_arm</robotNamespace>
      <!-- namespace for controllers etc... -->
    </plugin>
  </gazebo>
  <!-- GAZEBO COLORS -->
  <gazebo reference="wall_link">
    <visual>
      <material>
        <ambient>0.4 0.7 0.4 0.6</ambient>
        <diffuse>0.4 0.7 0.4 0.6</diffuse>
        <specular>0.4 0.7 0.4 0.6</specular>
        <emissive>0.0 0.0 0.0 0.0</emissive>
      </material>
    </visual>
  </gazebo>
  <gazebo reference="ombro_link">
    <visual>
      <material>
        <ambient>0.6 0.6 0.6 1.0</ambient>
        <diffuse>0.6 0.6 0.6 1.0</diffuse>
        <specular>0.6 0.6 0.6 1.0</specular>
        <emissive>0.0 0.0 0.0 0.0</emissive>
      </material>
    </visual>
  </gazebo>
  <gazebo reference="gripper_link">
    <visual>
      <material>
        <ambient>0.4 0.4 0.7 1.0</ambient>
        <diffuse>0.4 0.4 0.7 1.0</diffuse>
        <specular>0.4 0.4 0.7 1.0</specular>
        <emissive>0.0 0.0 0.0 0.0</emissive>
      </material>
    </visual>
  </gazebo>
  <gazebo reference="Box0_link">
    <visual>
      <material>
        <ambient>0 0 0 1.0</ambient>
        <diffuse>0 0 0 1.0</diffuse>
        <specular>0 0 0 1.0</specular>
        <emissive>0.0 0.0 0.0 0.0</emissive>
      </material>
    </visual>
  </gazebo>
  <gazebo reference="Box1_link">
    <visual>
      <material>
        <ambient>0 0 0 1.0</ambient>
        <diffuse>0 0 0 1.0</diffuse>
        <specular>0 0 0 1.0</specular>
        <emissive>0.0 0.0 0.0 0.0</emissive>
      </material>
    </visual>
  </gazebo>
  <gazebo reference="Box2_link">
    <visual>
      <material>
        <ambient>0 0 0 1.0</ambient>
        <diffuse>0 0 0 1.0</diffuse>
        <specular>0 0 0 1.0</specular>
        <emissive>0.0 0.0 0.0 0.0</emissive>
      </material>
    </visual>
  </gazebo>
  <gazebo reference="Box3_link">
    <visual>
      <material>
        <ambient>0 0 0 1.0</ambient>
        <diffuse>0 0 0 1.0</diffuse>
        <specular>0 0 0 1.0</specular>
        <emissive>0.0 0.0 0.0 0.0</emissive>
      </material>
    </visual>
  </gazebo>
  <gazebo reference="Tube0_link">
    <visual>
      <material>
        <ambient>0.7 0.3 0.3 1.0</ambient>
        <diffuse>0.7 0.3 0.3 1.0</diffuse>
        <specular>0.7 0.3 0.3 1.0</specular>
        <emissive>0.0 0.0 0.0 0.0</emissive>
      </material>
    </visual>
  </gazebo>
  <gazebo reference="Tube1_link">
    <visual>
      <material>
        <ambient>0.7 0.3 0.3 1.0</ambient>
        <diffuse>0.7 0.3 0.3 1.0</diffuse>
        <specular>0.7 0.3 0.3 1.0</specular>
        <emissive>0.0 0.0 0.0 0.0</emissive>
      </material>
    </visual>
  </gazebo>
  <!-- Didn't work
	<xacro:macro name="gazebo_propertys" params="link_name">
		<gazebo reference="${link_name}">
			<turnGravityOff>true</turnGravityOff>
		</gazebo>
    </xacro:macro>
    <xacro:gazebo_propertys link_name="Box0_link" />
    <xacro:gazebo_propertys link_name="Box1_link" />
    <xacro:gazebo_propertys link_name="Box2_link" />
    <xacro:gazebo_propertys link_name="Box3_link" />
    <xacro:gazebo_propertys link_name="Box4_link" />
    <xacro:gazebo_propertys link_name="Tube0_link" />
    <xacro:gazebo_propertys link_name="Tube1_link" />
    <xacro:gazebo_propertys link_name="wall_link" />
    <xacro:gazebo_propertys link_name="ombro_link" />
    <xacro:gazebo_propertys link_name="gripper_link" />
    -->
</robot>

